<?xml version="1.0" encoding="utf-8"?>
<!-- =================================================================================== -->
<!-- |    This document was autogenerated by xacro from panda_azure_kinect.urdf.xacro  | -->
<!-- |    EDITING THIS FILE BY HAND IS NOT RECOMMENDED                                 | -->
<!-- =================================================================================== -->
<robot name="panda_kinect">
  <!-- THE ROBOT -->
  <link name="panda_link0">
    <visual>
      <geometry>
        <mesh filename="package://panda-primitives/meshes/visual/link0.dae"/>
      </geometry>
    </visual>
    <collision>
      <geometry>
        <mesh filename="package://panda-primitives/meshes/collision/link0.stl"/>
      </geometry>
    </collision>
  </link>
  <link name="panda_link1">
    <visual>
      <geometry>
        <mesh filename="package://panda-primitives/meshes/visual/link1.dae"/>
      </geometry>
    </visual>
    <collision>
      <geometry>
        <mesh filename="package://panda-primitives/meshes/collision/link1.stl"/>
      </geometry>
    </collision>
  </link>
  <joint name="panda_joint1" type="revolute">
    <safety_controller k_position="100.0" k_velocity="40.0" soft_lower_limit="-2.8973" soft_upper_limit="2.8973"/>
    <origin rpy="0 0 0" xyz="0 0 0.333"/>
    <parent link="panda_link0"/>
    <child link="panda_link1"/>
    <axis xyz="0 0 1"/>
    <limit effort="87" lower="-2.8973" upper="2.8973" velocity="2.1750"/>
  </joint>
  <link name="panda_link2">
    <visual>
      <geometry>
        <mesh filename="package://panda-primitives/meshes/visual/link2.dae"/>
      </geometry>
    </visual>
    <collision>
      <geometry>
        <mesh filename="package://panda-primitives/meshes/collision/link2.stl"/>
      </geometry>
    </collision>
  </link>
  <joint name="panda_joint2" type="revolute">
    <safety_controller k_position="100.0" k_velocity="40.0" soft_lower_limit="-1.7628" soft_upper_limit="1.7628"/>
    <origin rpy="-1.57079632679 0 0" xyz="0 0 0"/>
    <parent link="panda_link1"/>
    <child link="panda_link2"/>
    <axis xyz="0 0 1"/>
    <limit effort="87" lower="-1.7628" upper="1.7628" velocity="2.1750"/>
  </joint>
  <link name="panda_link3">
    <visual>
      <geometry>
        <mesh filename="package://panda-primitives/meshes/visual/link3.dae"/>
      </geometry>
    </visual>
    <collision>
      <geometry>
        <mesh filename="package://panda-primitives/meshes/collision/link3.stl"/>
      </geometry>
    </collision>
  </link>
  <joint name="panda_joint3" type="revolute">
    <safety_controller k_position="100.0" k_velocity="40.0" soft_lower_limit="-2.8973" soft_upper_limit="2.8973"/>
    <origin rpy="1.57079632679 0 0" xyz="0 -0.316 0"/>
    <parent link="panda_link2"/>
    <child link="panda_link3"/>
    <axis xyz="0 0 1"/>
    <limit effort="87" lower="-2.8973" upper="2.8973" velocity="2.1750"/>
  </joint>
  <link name="panda_link4">
    <visual>
      <geometry>
        <mesh filename="package://panda-primitives/meshes/visual/link4.dae"/>
      </geometry>
    </visual>
    <collision>
      <geometry>
        <mesh filename="package://panda-primitives/meshes/collision/link4.stl"/>
      </geometry>
    </collision>
  </link>
  <joint name="panda_joint4" type="revolute">
    <safety_controller k_position="100.0" k_velocity="40.0" soft_lower_limit="-3.0718" soft_upper_limit="-0.0698"/>
    <origin rpy="1.57079632679 0 0" xyz="0.0825 0 0"/>
    <parent link="panda_link3"/>
    <child link="panda_link4"/>
    <axis xyz="0 0 1"/>
    <limit effort="87" lower="-3.0718" upper="-0.0698" velocity="2.1750"/>
  </joint>
  <link name="panda_link5">
    <visual>
      <geometry>
        <mesh filename="package://panda-primitives/meshes/visual/link5.dae"/>
      </geometry>
    </visual>
    <collision>
      <geometry>
        <mesh filename="package://panda-primitives/meshes/collision/link5.stl"/>
      </geometry>
    </collision>
  </link>
  <joint name="panda_joint5" type="revolute">
    <safety_controller k_position="100.0" k_velocity="40.0" soft_lower_limit="-2.8973" soft_upper_limit="2.8973"/>
    <origin rpy="-1.57079632679 0 0" xyz="-0.0825 0.384 0"/>
    <parent link="panda_link4"/>
    <child link="panda_link5"/>
    <axis xyz="0 0 1"/>
    <limit effort="12" lower="-2.8973" upper="2.8973" velocity="2.6100"/>
  </joint>
  <link name="panda_link6">
    <visual>
      <geometry>
        <mesh filename="package://panda-primitives/meshes/visual/link6.dae"/>
      </geometry>
    </visual>
    <collision>
      <geometry>
        <mesh filename="package://panda-primitives/meshes/collision/link6.stl"/>
      </geometry>
    </collision>
  </link>
  <joint name="panda_joint6" type="revolute">
    <safety_controller k_position="100.0" k_velocity="40.0" soft_lower_limit="-0.0175" soft_upper_limit="3.7525"/>
    <origin rpy="1.57079632679 0 0" xyz="0 0 0"/>
    <parent link="panda_link5"/>
    <child link="panda_link6"/>
    <axis xyz="0 0 1"/>
    <limit effort="12" lower="-0.0175" upper="3.7525" velocity="2.6100"/>
  </joint>
  <link name="panda_link7">
    <visual>
      <geometry>
        <mesh filename="package://panda-primitives/meshes/visual/link7.dae"/>
      </geometry>
    </visual>
    <collision>
      <geometry>
        <mesh filename="package://panda-primitives/meshes/collision/link7.stl"/>
      </geometry>
    </collision>
  </link>
  <joint name="panda_joint7" type="revolute">
    <safety_controller k_position="100.0" k_velocity="40.0" soft_lower_limit="-2.8973" soft_upper_limit="2.8973"/>
    <origin rpy="1.57079632679 0 0" xyz="0.088 0 0"/>
    <parent link="panda_link6"/>
    <child link="panda_link7"/>
    <axis xyz="0 0 1"/>
    <limit effort="12" lower="-2.8973" upper="2.8973" velocity="2.6100"/>
  </joint>
  <link name="ft_sensor_link">
    <visual>
      <geometry>
        <mesh filename="package://panda-primitives/meshes/force_torque_sensor.dae"/>
      </geometry>
    </visual>
    <collision>
      <geometry>
        <mesh filename="package://panda-primitives/meshes/force_torque_sensor.stl"/>
      </geometry>
    </collision>
  </link>
  <joint name="ft_sensor_joint" type="fixed">
    <origin rpy="0 0 0" xyz="0 0 0.062"/>
    <parent link="panda_link7"/>
    <child link="ft_sensor_link"/>
    <axis xyz="0 0 0"/>
  </joint>
  <link name="panda_link8"/>
  <joint name="panda_joint8" type="fixed">
    <!--<origin rpy="0 0 0" xyz="0 0 0.107"/>-->
    <origin rpy="0 0 0" xyz="0 0 0.11"/>
    <!--Added offset for FT sensor-->
    <parent link="ft_sensor_link"/>
    <child link="panda_link8"/>
    <axis xyz="0 0 0"/>
  </joint>
  <joint name="panda_hand_joint" type="fixed">
    <parent link="panda_link8"/>
    <child link="panda_hand"/>
    <origin rpy="0 0 -0.785398163397" xyz="0 0 0"/>
  </joint>
  <link name="panda_hand">
    <visual>
      <geometry>
        <mesh filename="package://panda-primitives/meshes/visual/hand.dae"/>
      </geometry>
    </visual>
    <collision>
      <geometry>
        <mesh filename="package://panda-primitives/meshes/collision/hand.stl"/>
      </geometry>
    </collision>
  </link>
  <link name="panda_leftfinger">
    <visual>
      <geometry>
        <mesh filename="package://panda-primitives/meshes/visual/finger.dae"/>
      </geometry>
    </visual>
    <collision>
      <geometry>
        <mesh filename="package://panda-primitives/meshes/collision/finger.stl"/>
      </geometry>
    </collision>
  </link>
  <link name="panda_rightfinger">
    <visual>
      <origin rpy="0 0 3.14159265359" xyz="0 0 0"/>
      <geometry>
        <mesh filename="package://panda-primitives/meshes/visual/finger.dae"/>
      </geometry>
    </visual>
    <collision>
      <origin rpy="0 0 3.14159265359" xyz="0 0 0"/>
      <geometry>
        <mesh filename="package://panda-primitives/meshes/collision/finger.stl"/>
      </geometry>
    </collision>
  </link>
  <joint name="panda_finger_joint1" type="prismatic">
    <parent link="panda_hand"/>
    <child link="panda_leftfinger"/>
    <origin rpy="0 0 0" xyz="0 0 0.0584"/>
    <axis xyz="0 1 0"/>
    <limit effort="20" lower="0.0" upper="0.04" velocity="0.2"/>
  </joint>
  <joint name="panda_finger_joint2" type="prismatic">
    <parent link="panda_hand"/>
    <child link="panda_rightfinger"/>
    <origin rpy="0 0 0" xyz="0 0 0.0584"/>
    <axis xyz="0 -1 0"/>
    <limit effort="20" lower="0.0" upper="0.04" velocity="0.2"/>
    <mimic joint="panda_finger_joint1"/>
  </joint>
  <material name="black">
    <color rgba="0. 0. 0. 1"/>
  </material>
  <material name="dark_grey">
    <color rgba="0.1 0.1 0.1 1"/>
  </material>
  <material name="grey">
    <color rgba="0.6 0.6 0.6 1"/>
  </material>
  <material name="white">
    <color rgba="0.9 0.9 0.9 1"/>
  </material>


  <!--  ########################## -->
  <!--  # Camera         -->
  <!--  ########################## -->

  <link name="camera_body">
    <visual>
      <origin rpy="0 3.1416 0"  xyz=".047 0.04 0.0115"/>
      <geometry>
        <mesh filename="package://panda-primitives/meshes/visual/kinect-model.stl"/>
      </geometry>
      <material name="white"/>
    </visual>
  </link>
  <link name="panda_flange"/>
  <joint name="panda_flange_joint" type="fixed">
    <parent link="ft_sensor_link"/>
    <child link="panda_flange"/>
    <origin rpy="0 0 -0.785398163397" xyz="0 0 0.043"/>
  </joint>


  <link name="camera_base">
  </link>

  <joint name="fake_base" type="fixed">
    <parent link="panda_flange"/>
    <child link="camera_basenonrotated"/>
    <!-- z is 11.4808 mm for panda flange to top of camera mount + 15.20653 from flange mount to tripod mount-->
    <origin rpy="3.14 -1.57 0.0" xyz="0.093997 0.0 0.0266868"/>
  </joint>

  <link name="camera_base_rgb">
  </link>

  <joint name="camera_base_rgb_joint" type="fixed">
    <parent link="camera_base"/>
    <child link="camera_base_rgb"/>
    <origin rpy="0.0 0.0 0.0" xyz="0.0 -0.03 0.0"/>
  </joint>

  <link name="camera_basenonrotated">
  </link>
  <joint name="camera_rotation" type="fixed">
    <parent link="camera_basenonrotated"/>
    <child link="camera_tripod"/>
    <origin rpy="0 -0.16069 0" xyz="0.0 0.0 0.0"/>
  </joint>
  <link name="camera_tripod">
  </link> 
  <joint name="camera_tripod_joint" type="fixed">
    <parent link="camera_tripod"/>
    <child link="camera_base"/>
    <origin rpy="0 0 0" xyz="0.062 0.0 0.0068"/>
  </joint>
  <joint name="camera_base_to_body" type="fixed">
    <parent link="camera_base"/>
    <child link="camera_body"/>
    <origin rpy="0. 0. 0." xyz="-0.0757 0. 0.008"/>
  </joint>
  <link name="camera_holder">
    <visual>
      <origin rpy="0 0 0"  xyz="0 0 0"/>
      <geometry>
        <mesh filename="package://panda-primitives/meshes/camera_holder_assem.STL"/>
      </geometry>
      <material name="grey"/>
    </visual>
  </link>
  <joint name="camera_holder_joint" type="fixed">
    <parent link="panda_flange"/>
    <child link="camera_holder"/>
    <!-- z is 11.4808 mm for panda flange to top of camera mount + 15.20653 from flange mount to tripod mount-->
    <origin rpy="3.14 0.0 0.0" xyz="0 0 0.0114808"/>
  </joint>

</robot>

